Workbook

Sheet Raw Data
A1: Order ID | B1: Order Date | C1: Ship Date | D1: Ship Mode | E1: Customer Name | F1: Segment | G1: Region | H1: State | I1: City | J1: Category | K1: Product Name | L1: Quantity | M1: Unit Price | N1: Discount | O1: Sales | P1: Profit
A2: ORD-1906 | B2: 2023-01-01 | C2: 2023-01-05 | D2: Standard | E2: Aarav Reddy | F2: Home Office | G2: East | H2: Bihar | I2: Gaya | J2: Clothing | K2: Formal Shirt | L2: 5 | M2: 899.62 | N2: 0.15 | O2: 3823.39 | P2: 580.56
A3: ORD-1536 | B3: 2023-01-01 | C3: 2023-01-06 | D3: Standard | E3: Isha Nair | F3: Consumer | G3: East | H3: Odisha | I3: Cuttack | J3: Clothing | K3: Denim Jeans | L3: 6 | M3: 1190.33 | N3: 0 | O3: 7141.98 | P3: 1090.81
A4: ORD-2552 | B4: 2023-01-02 | C4: 2023-01-07 | D4: Standard | E4: Anika Rao | F4: Corporate | G4: East | H4: Odisha | I4: Rourkela | J4: Clothing | K4: Sports Shoes | L4: 4 | M4: 1405.96 | N4: 0.05 | O4: 5342.65 | P4: 776.4
A5: ORD-2757 | B5: 2023-01-02 | C5: 2023-01-05 | D5: Express | E5: Myra Kapoor | F5: Corporate | G5: West | H5: Goa | I5: Panaji | J5: Furniture | K5: Office Chair | L5: 1 | M5: 12574.45 | N5: 0 | O5: 12574.45 | P5: 987.07
A6: ORD-2897 | B6: 2023-01-03 | C6: 2023-01-07 | D6: Standard | E6: Pooja Kapoor | F6: Corporate | G6: West | H6: Maharashtra | I6: Pune | J6: Stationery | K6: Whiteboard | L6: 2 | M6: 374.5 | N6: 0.2 | O6: 599.2 | P6: 110.75
A7: ORD-1453 | B7: 2023-01-03 | C7: 2023-01-07 | D7: Standard | E7: Ishaan Reddy | F7: Corporate | G7: North | H7: Uttar Pradesh | I7: Kanpur | J7: Home & Kitchen | K7: Cutlery Set | L7: 6 | M7: 3764.62 | N7: 0 | O7: 22587.72 | P7: 4702.38
A8: ORD-2437 | B8: 2023-01-03 | C8: 2023-01-07 | D8: Standard | E8: Karan Patel | F8: Consumer | G8: South | H8: Tamil Nadu | I8: Chennai | J8: Furniture | K8: Wardrobe | L8: 7 | M8: 16794.9 | N8: 0.05 | O8: 111686.09 | P8: 14140.01
A9: ORD-1221 | B9: 2023-01-03 | C9: 2023-01-05 | D9: Express | E9: Myra Iyer | F9: Corporate | G9: East | H9: Bihar | I9: Muzaffarpur | J9: Electronics | K9: Smartwatch | L9: 7 | M9: 1586.78 | N9: 0.1 | O9: 9996.71 | P9: 762.31
A10: ORD-1341 | B10: 2023-01-04 | C10: 2023-01-07 | D10: Express | E10: Ananya Bose | F10: Consumer | G10: West | H10: Maharashtra | I10: Nagpur | J10: Clothing | K10: Sports Shoes | L10: 2 | M10: 1348.92 | N10: 0.15 | O10: 2293.16 | P10: 396.75
A11: ORD-2771 | B11: 2023-01-04 | C11: 2023-01-10 | D11: Standard | E11: Suresh Chauhan | F11: Consumer | G11: West | H11: Gujarat | I11: Vadodara | J11: Clothing | K11: Denim Jeans | L11: 4 | M11: 1740.42 | N11: 0 | O11: 6961.68 | P11: 1257.55
A12: ORD-1007 | B12: 2023-01-04 | C12: 2023-01-08 | D12: Standard | E12: Pooja Joshi | F12: Corporate | G12: East | H12: Odisha | I12: Rourkela | J12: Home & Kitchen | K12: LED Lamp | L12: 3 | M12: 3912.84 | N12: 0.15 | O12: 9977.74 | P12: 1342.54
A13: ORD-2681 | B13: 2023-01-05 | C13: 2023-01-09 | D13: Standard | E13: Vivaan Mukherjee | F13: Consumer | G13: South | H13: Karnataka | I13: Bengaluru | J13: Electronics | K13: Power Bank | L13: 2 | M13: 2229.95 | N13: 0 | O13: 4459.9 | P13: 587.17
... A2201: ORD-1138 | B2201: 2024-12-31 | C2201: 2025-01-04 | D2201: Standard | E2201: Karan Rao | F2201: Consumer | G2201: East | H2201: Odisha | I2201: Cuttack | J2201: Stationery | K2201: Sketch Kit | L2201: 1 | M2201: 944.81 | N2201: 0.05 | O2201: 897.57 | P2201: 302.72

Sheet Analysis
A1: Sales Analysis
A2: All figures calculated live from Raw Data using SUMIFS / COUNTIFS / AVERAGEIFS
A4: 1. Sales & Profit by Region
A5: Region | B5: Total Sales | C5: Total Profit | D5: Profit Margin % | E5: Order Count | F5: Avg Order Value
A6: East | B6: =SUMIF('Raw Data'!$G:$G,$A6,'Raw Data'!$O:$O) | C6: =SUMIF('Raw Data'!$G:$G,$A6,'Raw Data'!$P:$P) | D6: =IFERROR(C6/B6,0) | E6: =COUNTIF('Raw Data'!$G:$G,$A6) | F6: =IFERROR(B6/E6,0)
A7: North | B7: =SUMIF('Raw Data'!$G:$G,$A7,'Raw Data'!$O:$O) | C7: =SUMIF('Raw Data'!$G:$G,$A7,'Raw Data'!$P:$P) | D7: =IFERROR(C7/B7,0) | E7: =COUNTIF('Raw Data'!$G:$G,$A7) | F7: =IFERROR(B7/E7,0)
A8: South | B8: =SUMIF('Raw Data'!$G:$G,$A8,'Raw Data'!$O:$O) | C8: =SUMIF('Raw Data'!$G:$G,$A8,'Raw Data'!$P:$P) | D8: =IFERROR(C8/B8,0) | E8: =COUNTIF('Raw Data'!$G:$G,$A8) | F8: =IFERROR(B8/E8,0)
A9: West | B9: =SUMIF('Raw Data'!$G:$G,$A9,'Raw Data'!$O:$O) | C9: =SUMIF('Raw Data'!$G:$G,$A9,'Raw Data'!$P:$P) | D9: =IFERROR(C9/B9,0) | E9: =COUNTIF('Raw Data'!$G:$G,$A9) | F9: =IFERROR(B9/E9,0)
A10: TOTAL | B10: =SUM(B6:B9) | C10: =SUM(C6:C9) | E10: =SUM(E6:E9)
A11: 2. Sales & Profit by Category
A12: Category | B12: Total Sales | C12: Total Profit | D12: Profit Margin % | E12: Units Sold | F12: Avg Discount %
A13: Clothing | B13: =SUMIF('Raw Data'!$J:$J,$A13,'Raw Data'!$O:$O) | C13: =SUMIF('Raw Data'!$J:$J,$A13,'Raw Data'!$P:$P) | D13: =IFERROR(C13/B13,0) | E13: =SUMIF('Raw Data'!$J:$J,$A13,'Raw Data'!$L:$L) | F13: =AVERAGEIF('Raw Data'!$J:$J,$A13,'Raw Data'!$N:$N)
A14: Electronics | B14: =SUMIF('Raw Data'!$J:$J,$A14,'Raw Data'!$O:$O) | C14: =SUMIF('Raw Data'!$J:$J,$A14,'Raw Data'!$P:$P) | D14: =IFERROR(C14/B14,0) | E14: =SUMIF('Raw Data'!$J:$J,$A14,'Raw Data'!$L:$L) | F14: =AVERAGEIF('Raw Data'!$J:$J,$A14,'Raw Data'!$N:$N)
A15: Furniture | B15: =SUMIF('Raw Data'!$J:$J,$A15,'Raw Data'!$O:$O) | C15: =SUMIF('Raw Data'!$J:$J,$A15,'Raw Data'!$P:$P) | D15: =IFERROR(C15/B15,0) | E15: =SUMIF('Raw Data'!$J:$J,$A15,'Raw Data'!$L:$L) | F15: =AVERAGEIF('Raw Data'!$J:$J,$A15,'Raw Data'!$N:$N)
A16: Home & Kitchen | B16: =SUMIF('Raw Data'!$J:$J,$A16,'Raw Data'!$O:$O) | C16: =SUMIF('Raw Data'!$J:$J,$A16,'Raw Data'!$P:$P) | D16: =IFERROR(C16/B16,0) | E16: =SUMIF('Raw Data'!$J:$J,$A16,'Raw Data'!$L:$L) | F16: =AVERAGEIF('Raw Data'!$J:$J,$A16,'Raw Data'!$N:$N)
A17: Stationery | B17: =SUMIF('Raw Data'!$J:$J,$A17,'Raw Data'!$O:$O) | C17: =SUMIF('Raw Data'!$J:$J,$A17,'Raw Data'!$P:$P) | D17: =IFERROR(C17/B17,0) | E17: =SUMIF('Raw Data'!$J:$J,$A17,'Raw Data'!$L:$L) | F17: =AVERAGEIF('Raw Data'!$J:$J,$A17,'Raw Data'!$N:$N)
A19: 3. Monthly Sales Trend
A20: Month | B20: Total Sales | C20: Total Profit | D20: Order Count
A21: 2023-01 | B21: =SUMPRODUCT(('Raw Data'!$B2:$B2201>=DATE(VALUE(LEFT($A21,4)),VALUE(MID($A21,6,2)),1))*('Raw Data'!$B2:$B2201<EDATE(DATE(VALUE(LEFT($A21,4)),VALUE(MID($A21,6,2)),1),1))*'Raw Data'!$O2:$O2201) | C21: =SUMPRODUCT(('Raw Data'!$B2:$B2201>=DATE(VALUE(LEFT($A21,4)),VALUE(MID($A21,6,2)),1))*('Raw Data'!$B2:$B2201<EDATE(DATE(VALUE(LEFT($A21,4)),VALUE(MID($A21,6,2)),1),1))*'Raw Data'!$P2:$P2201) | D21: =SUMPRODUCT(('Raw Data'!$B2:$B2201>=DATE(VALUE(LEFT($A21,4)),VALUE(MID($A21,6,2)),1))*('Raw Data'!$B2:$B2201<EDATE(DATE(VALUE(LEFT($A21,4)),VALUE(MID($A21,6,2)),1),1)))
A22: 2023-02 | B22: =SUMPRODUCT(('Raw Data'!$B2:$B2201>=DATE(VALUE(LEFT($A22,4)),VALUE(MID($A22,6,2)),1))*('Raw Data'!$B2:$B2201<EDATE(DATE(VALUE(LEFT($A22,4)),VALUE(MID($A22,6,2)),1),1))*'Raw Data'!$O2:$O2201) | C22: =SUMPRODUCT(('Raw Data'!$B2:$B2201>=DATE(VALUE(LEFT($A22,4)),VALUE(MID($A22,6,2)),1))*('Raw Data'!$B2:$B2201<EDATE(DATE(VALUE(LEFT($A22,4)),VALUE(MID($A22,6,2)),1),1))*'Raw Data'!$P2:$P2201) | D22: =SUMPRODUCT(('Raw Data'!$B2:$B2201>=DATE(VALUE(LEFT($A22,4)),VALUE(MID($A22,6,2)),1))*('Raw Data'!$B2:$B2201<EDATE(DATE(VALUE(LEFT($A22,4)),VALUE(MID($A22,6,2)),1),1)))
A23: 2023-03 | B23: =SUMPRODUCT(('Raw Data'!$B2:$B2201>=DATE(VALUE(LEFT($A23,4)),VALUE(MID($A23,6,2)),1))*('Raw Data'!$B2:$B2201<EDATE(DATE(VALUE(LEFT($A23,4)),VALUE(MID($A23,6,2)),1),1))*'Raw Data'!$O2:$O2201) | C23: =SUMPRODUCT(('Raw Data'!$B2:$B2201>=DATE(VALUE(LEFT($A23,4)),VALUE(MID($A23,6,2)),1))*('Raw Data'!$B2:$B2201<EDATE(DATE(VALUE(LEFT($A23,4)),VALUE(MID($A23,6,2)),1),1))*'Raw Data'!$P2:$P2201) | D23: =SUMPRODUCT(('Raw Data'!$B2:$B2201>=DATE(VALUE(LEFT($A23,4)),VALUE(MID($A23,6,2)),1))*('Raw Data'!$B2:$B2201<EDATE(DATE(VALUE(LEFT($A23,4)),VALUE(MID($A23,6,2)),1),1)))
A24: 2023-04 | B24: =SUMPRODUCT(('Raw Data'!$B2:$B2201>=DATE(VALUE(LEFT($A24,4)),VALUE(MID($A24,6,2)),1))*('Raw Data'!$B2:$B2201<EDATE(DATE(VALUE(LEFT($A24,4)),VALUE(MID($A24,6,2)),1),1))*'Raw Data'!$O2:$O2201) | C24: =SUMPRODUCT(('Raw Data'!$B2:$B2201>=DATE(VALUE(LEFT($A24,4)),VALUE(MID($A24,6,2)),1))*('Raw Data'!$B2:$B2201<EDATE(DATE(VALUE(LEFT($A24,4)),VALUE(MID($A24,6,2)),1),1))*'Raw Data'!$P2:$P2201) | D24: =SUMPRODUCT(('Raw Data'!$B2:$B2201>=DATE(VALUE(LEFT($A24,4)),VALUE(MID($A24,6,2)),1))*('Raw Data'!$B2:$B2201<EDATE(DATE(VALUE(LEFT($A24,4)),VALUE(MID($A24,6,2)),1),1)))
A25: 2023-05 | B25: =SUMPRODUCT(('Raw Data'!$B2:$B2201>=DATE(VALUE(LEFT($A25,4)),VALUE(MID($A25,6,2)),1))*('Raw Data'!$B2:$B2201<EDATE(DATE(VALUE(LEFT($A25,4)),VALUE(MID($A25,6,2)),1),1))*'Raw Data'!$O2:$O2201) | C25: =SUMPRODUCT(('Raw Data'!$B2:$B2201>=DATE(VALUE(LEFT($A25,4)),VALUE(MID($A25,6,2)),1))*('Raw Data'!$B2:$B2201<EDATE(DATE(VALUE(LEFT($A25,4)),VALUE(MID($A25,6,2)),1),1))*'Raw Data'!$P2:$P2201) | D25: =SUMPRODUCT(('Raw Data'!$B2:$B2201>=DATE(VALUE(LEFT($A25,4)),VALUE(MID($A25,6,2)),1))*('Raw Data'!$B2:$B2201<EDATE(DATE(VALUE(LEFT($A25,4)),VALUE(MID($A25,6,2)),1),1)))
A26: 2023-06 | B26: =SUMPRODUCT(('Raw Data'!$B2:$B2201>=DATE(VALUE(LEFT($A26,4)),VALUE(MID($A26,6,2)),1))*('Raw Data'!$B2:$B2201<EDATE(DATE(VALUE(LEFT($A26,4)),VALUE(MID($A26,6,2)),1),1))*'Raw Data'!$O2:$O2201) | C26: =SUMPRODUCT(('Raw Data'!$B2:$B2201>=DATE(VALUE(LEFT($A26,4)),VALUE(MID($A26,6,2)),1))*('Raw Data'!$B2:$B2201<EDATE(DATE(VALUE(LEFT($A26,4)),VALUE(MID($A26,6,2)),1),1))*'Raw Data'!$P2:$P2201) | D26: =SUMPRODUCT(('Raw Data'!$B2:$B2201>=DATE(VALUE(LEFT($A26,4)),VALUE(MID($A26,6,2)),1))*('Raw Data'!$B2:$B2201<EDATE(DATE(VALUE(LEFT($A26,4)),VALUE(MID($A26,6,2)),1),1)))
A27: 2023-07 | B27: =SUMPRODUCT(('Raw Data'!$B2:$B2201>=DATE(VALUE(LEFT($A27,4)),VALUE(MID($A27,6,2)),1))*('Raw Data'!$B2:$B2201<EDATE(DATE(VALUE(LEFT($A27,4)),VALUE(MID($A27,6,2)),1),1))*'Raw Data'!$O2:$O2201) | C27: =SUMPRODUCT(('Raw Data'!$B2:$B2201>=DATE(VALUE(LEFT($A27,4)),VALUE(MID($A27,6,2)),1))*('Raw Data'!$B2:$B2201<EDATE(DATE(VALUE(LEFT($A27,4)),VALUE(MID($A27,6,2)),1),1))*'Raw Data'!$P2:$P2201) | D27: =SUMPRODUCT(('Raw Data'!$B2:$B2201>=DATE(VALUE(LEFT($A27,4)),VALUE(MID($A27,6,2)),1))*('Raw Data'!$B2:$B2201<EDATE(DATE(VALUE(LEFT($A27,4)),VALUE(MID($A27,6,2)),1),1)))
A28: 2023-08 | B28: =SUMPRODUCT(('Raw Data'!$B2:$B2201>=DATE(VALUE(LEFT($A28,4)),VALUE(MID($A28,6,2)),1))*('Raw Data'!$B2:$B2201<EDATE(DATE(VALUE(LEFT($A28,4)),VALUE(MID($A28,6,2)),1),1))*'Raw Data'!$O2:$O2201) | C28: =SUMPRODUCT(('Raw Data'!$B2:$B2201>=DATE(VALUE(LEFT($A28,4)),VALUE(MID($A28,6,2)),1))*('Raw Data'!$B2:$B2201<EDATE(DATE(VALUE(LEFT($A28,4)),VALUE(MID($A28,6,2)),1),1))*'Raw Data'!$P2:$P2201) | D28: =SUMPRODUCT(('Raw Data'!$B2:$B2201>=DATE(VALUE(LEFT($A28,4)),VALUE(MID($A28,6,2)),1))*('Raw Data'!$B2:$B2201<EDATE(DATE(VALUE(LEFT($A28,4)),VALUE(MID($A28,6,2)),1),1)))
A29: 2023-09 | B29: =SUMPRODUCT(('Raw Data'!$B2:$B2201>=DATE(VALUE(LEFT($A29,4)),VALUE(MID($A29,6,2)),1))*('Raw Data'!$B2:$B2201<EDATE(DATE(VALUE(LEFT($A29,4)),VALUE(MID($A29,6,2)),1),1))*'Raw Data'!$O2:$O2201) | C29: =SUMPRODUCT(('Raw Data'!$B2:$B2201>=DATE(VALUE(LEFT($A29,4)),VALUE(MID($A29,6,2)),1))*('Raw Data'!$B2:$B2201<EDATE(DATE(VALUE(LEFT($A29,4)),VALUE(MID($A29,6,2)),1),1))*'Raw Data'!$P2:$P2201) | D29: =SUMPRODUCT(('Raw Data'!$B2:$B2201>=DATE(VALUE(LEFT($A29,4)),VALUE(MID($A29,6,2)),1))*('Raw Data'!$B2:$B2201<EDATE(DATE(VALUE(LEFT($A29,4)),VALUE(MID($A29,6,2)),1),1)))
A30: 2023-10 | B30: =SUMPRODUCT(('Raw Data'!$B2:$B2201>=DATE(VALUE(LEFT($A30,4)),VALUE(MID($A30,6,2)),1))*('Raw Data'!$B2:$B2201<EDATE(DATE(VALUE(LEFT($A30,4)),VALUE(MID($A30,6,2)),1),1))*'Raw Data'!$O2:$O2201) | C30: =SUMPRODUCT(('Raw Data'!$B2:$B2201>=DATE(VALUE(LEFT($A30,4)),VALUE(MID($A30,6,2)),1))*('Raw Data'!$B2:$B2201<EDATE(DATE(VALUE(LEFT($A30,4)),VALUE(MID($A30,6,2)),1),1))*'Raw Data'!$P2:$P2201) | D30: =SUMPRODUCT(('Raw Data'!$B2:$B2201>=DATE(VALUE(LEFT($A30,4)),VALUE(MID($A30,6,2)),1))*('Raw Data'!$B2:$B2201<EDATE(DATE(VALUE(LEFT($A30,4)),VALUE(MID($A30,6,2)),1),1)))
A31: 2023-11 | B31: =SUMPRODUCT(('Raw Data'!$B2:$B2201>=DATE(VALUE(LEFT($A31,4)),VALUE(MID($A31,6,2)),1))*('Raw Data'!$B2:$B2201<EDATE(DATE(VALUE(LEFT($A31,4)),VALUE(MID($A31,6,2)),1),1))*'Raw Data'!$O2:$O2201) | C31: =SUMPRODUCT(('Raw Data'!$B2:$B2201>=DATE(VALUE(LEFT($A31,4)),VALUE(MID($A31,6,2)),1))*('Raw Data'!$B2:$B2201<EDATE(DATE(VALUE(LEFT($A31,4)),VALUE(MID($A31,6,2)),1),1))*'Raw Data'!$P2:$P2201) | D31: =SUMPRODUCT(('Raw Data'!$B2:$B2201>=DATE(VALUE(LEFT($A31,4)),VALUE(MID($A31,6,2)),1))*('Raw Data'!$B2:$B2201<EDATE(DATE(VALUE(LEFT($A31,4)),VALUE(MID($A31,6,2)),1),1)))
A32: 2023-12 | B32: =SUMPRODUCT(('Raw Data'!$B2:$B2201>=DATE(VALUE(LEFT($A32,4)),VALUE(MID($A32,6,2)),1))*('Raw Data'!$B2:$B2201<EDATE(DATE(VALUE(LEFT($A32,4)),VALUE(MID($A32,6,2)),1),1))*'Raw Data'!$O2:$O2201) | C32: =SUMPRODUCT(('Raw Data'!$B2:$B2201>=DATE(VALUE(LEFT($A32,4)),VALUE(MID($A32,6,2)),1))*('Raw Data'!$B2:$B2201<EDATE(DATE(VALUE(LEFT($A32,4)),VALUE(MID($A32,6,2)),1),1))*'Raw Data'!$P2:$P2201) | D32: =SUMPRODUCT(('Raw Data'!$B2:$B2201>=DATE(VALUE(LEFT($A32,4)),VALUE(MID($A32,6,2)),1))*('Raw Data'!$B2:$B2201<EDATE(DATE(VALUE(LEFT($A32,4)),VALUE(MID($A32,6,2)),1),1)))
A33: 2024-01 | B33: =SUMPRODUCT(('Raw Data'!$B2:$B2201>=DATE(VALUE(LEFT($A33,4)),VALUE(MID($A33,6,2)),1))*('Raw Data'!$B2:$B2201<EDATE(DATE(VALUE(LEFT($A33,4)),VALUE(MID($A33,6,2)),1),1))*'Raw Data'!$O2:$O2201) | C33: =SUMPRODUCT(('Raw Data'!$B2:$B2201>=DATE(VALUE(LEFT($A33,4)),VALUE(MID($A33,6,2)),1))*('Raw Data'!$B2:$B2201<EDATE(DATE(VALUE(LEFT($A33,4)),VALUE(MID($A33,6,2)),1),1))*'Raw Data'!$P2:$P2201) | D33: =SUMPRODUCT(('Raw Data'!$B2:$B2201>=DATE(VALUE(LEFT($A33,4)),VALUE(MID($A33,6,2)),1))*('Raw Data'!$B2:$B2201<EDATE(DATE(VALUE(LEFT($A33,4)),VALUE(MID($A33,6,2)),1),1)))
A34: 2024-02 | B34: =SUMPRODUCT(('Raw Data'!$B2:$B2201>=DATE(VALUE(LEFT($A34,4)),VALUE(MID($A34,6,2)),1))*('Raw Data'!$B2:$B2201<EDATE(DATE(VALUE(LEFT($A34,4)),VALUE(MID($A34,6,2)),1),1))*'Raw Data'!$O2:$O2201) | C34: =SUMPRODUCT(('Raw Data'!$B2:$B2201>=DATE(VALUE(LEFT($A34,4)),VALUE(MID($A34,6,2)),1))*('Raw Data'!$B2:$B2201<EDATE(DATE(VALUE(LEFT($A34,4)),VALUE(MID($A34,6,2)),1),1))*'Raw Data'!$P2:$P2201) | D34: =SUMPRODUCT(('Raw Data'!$B2:$B2201>=DATE(VALUE(LEFT($A34,4)),VALUE(MID($A34,6,2)),1))*('Raw Data'!$B2:$B2201<EDATE(DATE(VALUE(LEFT($A34,4)),VALUE(MID($A34,6,2)),1),1)))
A35: 2024-03 | B35: =SUMPRODUCT(('Raw Data'!$B2:$B2201>=DATE(VALUE(LEFT($A35,4)),VALUE(MID($A35,6,2)),1))*('Raw Data'!$B2:$B2201<EDATE(DATE(VALUE(LEFT($A35,4)),VALUE(MID($A35,6,2)),1),1))*'Raw Data'!$O2:$O2201) | C35: =SUMPRODUCT(('Raw Data'!$B2:$B2201>=DATE(VALUE(LEFT($A35,4)),VALUE(MID($A35,6,2)),1))*('Raw Data'!$B2:$B2201<EDATE(DATE(VALUE(LEFT($A35,4)),VALUE(MID($A35,6,2)),1),1))*'Raw Data'!$P2:$P2201) | D35: =SUMPRODUCT(('Raw Data'!$B2:$B2201>=DATE(VALUE(LEFT($A35,4)),VALUE(MID($A35,6,2)),1))*('Raw Data'!$B2:$B2201<EDATE(DATE(VALUE(LEFT($A35,4)),VALUE(MID($A35,6,2)),1),1)))
A36: 2024-04 | B36: =SUMPRODUCT(('Raw Data'!$B2:$B2201>=DATE(VALUE(LEFT($A36,4)),VALUE(MID($A36,6,2)),1))*('Raw Data'!$B2:$B2201<EDATE(DATE(VALUE(LEFT($A36,4)),VALUE(MID($A36,6,2)),1),1))*'Raw Data'!$O2:$O2201) | C36: =SUMPRODUCT(('Raw Data'!$B2:$B2201>=DATE(VALUE(LEFT($A36,4)),VALUE(MID($A36,6,2)),1))*('Raw Data'!$B2:$B2201<EDATE(DATE(VALUE(LEFT($A36,4)),VALUE(MID($A36,6,2)),1),1))*'Raw Data'!$P2:$P2201) | D36: =SUMPRODUCT(('Raw Data'!$B2:$B2201>=DATE(VALUE(LEFT($A36,4)),VALUE(MID($A36,6,2)),1))*('Raw Data'!$B2:$B2201<EDATE(DATE(VALUE(LEFT($A36,4)),VALUE(MID($A36,6,2)),1),1)))
A37: 2024-05 | B37: =SUMPRODUCT(('Raw Data'!$B2:$B2201>=DATE(VALUE(LEFT($A37,4)),VALUE(MID($A37,6,2)),1))*('Raw Data'!$B2:$B2201<EDATE(DATE(VALUE(LEFT($A37,4)),VALUE(MID($A37,6,2)),1),1))*'Raw Data'!$O2:$O2201) | C37: =SUMPRODUCT(('Raw Data'!$B2:$B2201>=DATE(VALUE(LEFT($A37,4)),VALUE(MID($A37,6,2)),1))*('Raw Data'!$B2:$B2201<EDATE(DATE(VALUE(LEFT($A37,4)),VALUE(MID($A37,6,2)),1),1))*'Raw Data'!$P2:$P2201) | D37: =SUMPRODUCT(('Raw Data'!$B2:$B2201>=DATE(VALUE(LEFT($A37,4)),VALUE(MID($A37,6,2)),1))*('Raw Data'!$B2:$B2201<EDATE(DATE(VALUE(LEFT($A37,4)),VALUE(MID($A37,6,2)),1),1)))
A38: 2024-06 | B38: =SUMPRODUCT(('Raw Data'!$B2:$B2201>=DATE(VALUE(LEFT($A38,4)),VALUE(MID($A38,6,2)),1))*('Raw Data'!$B2:$B2201<EDATE(DATE(VALUE(LEFT($A38,4)),VALUE(MID($A38,6,2)),1),1))*'Raw Data'!$O2:$O2201) | C38: =SUMPRODUCT(('Raw Data'!$B2:$B2201>=DATE(VALUE(LEFT($A38,4)),VALUE(MID($A38,6,2)),1))*('Raw Data'!$B2:$B2201<EDATE(DATE(VALUE(LEFT($A38,4)),VALUE(MID($A38,6,2)),1),1))*'Raw Data'!$P2:$P2201) | D38: =SUMPRODUCT(('Raw Data'!$B2:$B2201>=DATE(VALUE(LEFT($A38,4)),VALUE(MID($A38,6,2)),1))*('Raw Data'!$B2:$B2201<EDATE(DATE(VALUE(LEFT($A38,4)),VALUE(MID($A38,6,2)),1),1)))
A39: 2024-07 | B39: =SUMPRODUCT(('Raw Data'!$B2:$B2201>=DATE(VALUE(LEFT($A39,4)),VALUE(MID($A39,6,2)),1))*('Raw Data'!$B2:$B2201<EDATE(DATE(VALUE(LEFT($A39,4)),VALUE(MID($A39,6,2)),1),1))*'Raw Data'!$O2:$O2201) | C39: =SUMPRODUCT(('Raw Data'!$B2:$B2201>=DATE(VALUE(LEFT($A39,4)),VALUE(MID($A39,6,2)),1))*('Raw Data'!$B2:$B2201<EDATE(DATE(VALUE(LEFT($A39,4)),VALUE(MID($A39,6,2)),1),1))*'Raw Data'!$P2:$P2201) | D39: =SUMPRODUCT(('Raw Data'!$B2:$B2201>=DATE(VALUE(LEFT($A39,4)),VALUE(MID($A39,6,2)),1))*('Raw Data'!$B2:$B2201<EDATE(DATE(VALUE(LEFT($A39,4)),VALUE(MID($A39,6,2)),1),1)))
A40: 2024-08 | B40: =SUMPRODUCT(('Raw Data'!$B2:$B2201>=DATE(VALUE(LEFT($A40,4)),VALUE(MID($A40,6,2)),1))*('Raw Data'!$B2:$B2201<EDATE(DATE(VALUE(LEFT($A40,4)),VALUE(MID($A40,6,2)),1),1))*'Raw Data'!$O2:$O2201) | C40: =SUMPRODUCT(('Raw Data'!$B2:$B2201>=DATE(VALUE(LEFT($A40,4)),VALUE(MID($A40,6,2)),1))*('Raw Data'!$B2:$B2201<EDATE(DATE(VALUE(LEFT($A40,4)),VALUE(MID($A40,6,2)),1),1))*'Raw Data'!$P2:$P2201) | D40: =SUMPRODUCT(('Raw Data'!$B2:$B2201>=DATE(VALUE(LEFT($A40,4)),VALUE(MID($A40,6,2)),1))*('Raw Data'!$B2:$B2201<EDATE(DATE(VALUE(LEFT($A40,4)),VALUE(MID($A40,6,2)),1),1)))
A41: 2024-09 | B41: =SUMPRODUCT(('Raw Data'!$B2:$B2201>=DATE(VALUE(LEFT($A41,4)),VALUE(MID($A41,6,2)),1))*('Raw Data'!$B2:$B2201<EDATE(DATE(VALUE(LEFT($A41,4)),VALUE(MID($A41,6,2)),1),1))*'Raw Data'!$O2:$O2201) | C41: =SUMPRODUCT(('Raw Data'!$B2:$B2201>=DATE(VALUE(LEFT($A41,4)),VALUE(MID($A41,6,2)),1))*('Raw Data'!$B2:$B2201<EDATE(DATE(VALUE(LEFT($A41,4)),VALUE(MID($A41,6,2)),1),1))*'Raw Data'!$P2:$P2201) | D41: =SUMPRODUCT(('Raw Data'!$B2:$B2201>=DATE(VALUE(LEFT($A41,4)),VALUE(MID($A41,6,2)),1))*('Raw Data'!$B2:$B2201<EDATE(DATE(VALUE(LEFT($A41,4)),VALUE(MID($A41,6,2)),1),1)))
A42: 2024-10 | B42: =SUMPRODUCT(('Raw Data'!$B2:$B2201>=DATE(VALUE(LEFT($A42,4)),VALUE(MID($A42,6,2)),1))*('Raw Data'!$B2:$B2201<EDATE(DATE(VALUE(LEFT($A42,4)),VALUE(MID($A42,6,2)),1),1))*'Raw Data'!$O2:$O2201) | C42: =SUMPRODUCT(('Raw Data'!$B2:$B2201>=DATE(VALUE(LEFT($A42,4)),VALUE(MID($A42,6,2)),1))*('Raw Data'!$B2:$B2201<EDATE(DATE(VALUE(LEFT($A42,4)),VALUE(MID($A42,6,2)),1),1))*'Raw Data'!$P2:$P2201) | D42: =SUMPRODUCT(('Raw Data'!$B2:$B2201>=DATE(VALUE(LEFT($A42,4)),VALUE(MID($A42,6,2)),1))*('Raw Data'!$B2:$B2201<EDATE(DATE(VALUE(LEFT($A42,4)),VALUE(MID($A42,6,2)),1),1)))
...

Sheet Dashboard
B2: RETAIL SALES PERFORMANCE DASHBOARD
B3: Data period: Jan 2023 - Dec 2024 | Source: Raw Data sheet | All values auto-calculated
B5: Total Revenue | D5: Total Profit | F5: Overall Profit Margin | H5: Total Orders | J5: Avg Order Value | L5: Total Units Sold
B7: =SUM('Raw Data'!$O:$O) | D7: =SUM('Raw Data'!$P:$P) | F7: =SUM('Raw Data'!$P:$P)/SUM('Raw Data'!$O:$O) | H7: =COUNTA('Raw Data'!$O2:$O2201) | J7: =AVERAGE('Raw Data'!$O:$O) | L7: =SUM('Raw Data'!$L:$L)
